<?xml version="1.0"?>
<robot name="robot">

    <material name="black">
        <color rgba="0.03 0.03 0.03 1"/>
    </material>
    
    <material name="grey">
        <color rgba="0.3 0.3 0.3 1"/>
    </material>

    <material name="white">
        <color rgba="1 1 1 1"/>
    </material>
          
    <link name="base_link">
        <visual>
            <geometry>
                <cylinder length="1" radius="3"/>
            </geometry>
            <origin rpy="0 0 0" xyz="0 0 0.5"/>
            <material name="black"/>
        </visual>
    </link>
    
    <link name="top_plate">
        <visual>
            <!--
            <geometry>
                <mesh filename="package://basic_description/meshes/tp_assembly.stl"/>
            </geometry>
            -->
            <geometry>
                <cylinder length="0.06" radius="3"/>
            </geometry>
            <material name="grey"/>
            <origin rpy="0 0 0" xyz="0 0 1.25"/>
        </visual>
    </link>
    
    <link name="camera_mount">
        <visual>
            <geometry>
                <box size="0.05 0.7 0.9"/>
            </geometry>        
            <material name="white"/>
            <origin rpy="0 0.5 0" xyz="-1.5 0 1.6"/>
        </visual>
    </link>
    
    <joint name="base_to_plate" type="prismatic">
        <parent link="base_link"/>
        <child link="plate"/>
        <origin rpy="0 0 0" xyz="0 0 0"/>
        <axis xyz="0 0 1"/>
        <limit effort="100.0" lower="0" upper="4" velocity="0.1"/>
    </joint>
    
    <link name="plate">
        <visual>
            <geometry>
                <box size="0.7 0.7 0.05"/>
            </geometry>
            <origin rpy="0 0 1" xyz="0 0 1.025"/>
        </visual>
    </link>
</robot>